<?xml version="1.0"?>
<robot name="zx120" xmlns:xacro="http://www.ros.org/wiki/xacro">

	<!-- Import all Gazebo-customization elements, including Gazebo colors -->
	<xacro:include filename="$(find zx120_description)/urdf/zx120.gazebo" />
	<!-- Import Rviz colors -->
	<!-- <xacro:include filename="$(find zx120_description)/urdf/materials.xacro" /> -->

	<!-- Base Link -->
	<link name="base_link"/>
	<joint name="base_joint" type="fixed">
		<parent link="base_link"/>
		<child link="track_link"/>
	</joint>

	<!-- Base Link -->
	<link name="track_link">
		<visual>
			<geometry>
				<mesh filename="package://zx120_description/meshes/zx120-crawler.dae"/>
			</geometry>
		</visual>

		<collision>
			<geometry>
				<mesh filename="package://zx120_description/meshes/zx120-crawler.dae"/>
			</geometry>
		</collision>

		<inertial>
			<origin xyz="-0.155869 0 0.358402" rpy="0 0 0"/>
			<mass value="0.03"/>
			<inertia ixx="1.0" ixy="0.0" ixz="0.0"
								iyy="1.0" iyz="0.0"
											izz="1.0"/>
		</inertial>
	</link>

	<!-- body axis -->
	<joint name="swing_joint" type="continuous">
		<origin xyz="0 0 1"/>
		<axis xyz="0 0 2"/>
		<parent link="track_link"/>
		<child link="body_link"/>
	</joint>

	<link name="body_link">
		<visual>
			<origin xyz="0 0 0"/>
			<geometry>
				<mesh filename="package://zx120_description/meshes/zx120-body.dae"/>
			</geometry>
		</visual>

		<collision>
			<origin xyz="0 0 0"/>
			<geometry>
				<mesh filename="package://zx120_description/meshes/zx120-body.dae"/>
			</geometry>
		</collision>

		<inertial>
			<origin xyz="-0.501522 0 1.191169" rpy="0 0 0"/>
			<mass value="0.03"/>
			<inertia ixx="1.0" ixy="0.0" ixz="0.0"
								iyy="1.0" iyz="0.0"
											izz="1.0"/>
		</inertial>
	</link>

	<!-- boom axis -->
	<joint name="boom_joint" type="revolute">
		<origin xyz="0.15433 -0.16443 0.31327"/>
		<axis xyz="0 1 0"/>
		<parent link="body_link"/>
		<child link="boom_link"/>
		<limit lower="${radians(-70)}" upper="${radians(30)}" effort="500" velocity="6.159937255"/>
	</joint>

	<joint name="boom_cylinder_head_joint" type="continuous">
		<origin xyz="0.556105 -0.164428 0.032962"/>
		<axis xyz="0 1 0"/>
		<parent link="body_link"/>
		<child link="boom_cylinder_head_link"/>
		<mimic joint="boom_joint" multiplier="${60/70}"/>
	</joint>
	<gazebo>
		<plugin name="boom_cylinder_head_joint_mimic_joint_plugin"
				filename="libroboticsgroup_upatras_gazebo_mimic_joint_plugin.so">
			<joint>boom_joint</joint>
			<mimicJoint>boom_cylinder_head_joint</mimicJoint>
			<multiplier>${60/70}</multiplier>
			<offset>0</offset>
			<robotNamespace>/zx120</robotNamespace>
		</plugin>
	</gazebo>

	<joint name="boom_cylinder_rod_joint" type="prismatic">
		<origin xyz="0 0 0"/>
		<axis xyz="0.802033 0 1.847495"/>
		<parent link="boom_cylinder_head_link"/>
		<child link="boom_cylinder_rod_link"/>
		<limit lower="-2" upper="2" effort="500" velocity="6.159937255"/>
		<mimic joint="boom_joint" multiplier="${0.39/-1.22}"/>
	</joint>
	<gazebo>
		<plugin name="boom_cylinder_rod_joint_mimic_joint_plugin"
				filename="libroboticsgroup_upatras_gazebo_mimic_joint_plugin.so">
			<joint>boom_joint</joint>
			<mimicJoint>boom_cylinder_rod_joint</mimicJoint>
			<multiplier>${0.39/-1.22}</multiplier>
			<offset>0</offset>
			<robotNamespace>/zx120</robotNamespace>
		</plugin>
	</gazebo>

	<joint name="arm_cylinder_head_joint" type="fixed">
		<origin xyz="2.053030 0 1.991444"/>
		<axis xyz="0 1 0"/>
		<parent link="boom_link"/>
		<child link="arm_cylinder_head_link"/>
	</joint>

	<joint name="arm_cylinder_rod_joint" type="prismatic">
		<origin xyz="0 0 0"/>
		<axis xyz="2.36471 0 0"/>
		<parent link="arm_cylinder_head_link"/>
		<child link="arm_cylinder_rod_link"/>
		<limit lower="-2" upper="2" effort="500" velocity="6.159937255"/>
		<mimic joint="arm_joint" multiplier="${0.4/radians(50)}"/>
	</joint>
	<gazebo>
		<plugin name="arm_cylinder_rod_joint_mimic_joint_plugin"
				filename="libroboticsgroup_upatras_gazebo_mimic_joint_plugin.so">
			<joint>arm_joint</joint>
			<mimicJoint>arm_cylinder_rod_joint</mimicJoint>
			<multiplier>${0.4/radians(50)}</multiplier>
			<offset>0</offset>
			<robotNamespace>/zx120</robotNamespace>
		</plugin>
	</gazebo>

	<joint name="bucket_cylinder_head_joint" type="fixed">
		<origin xyz="0.605825 0 -0.364793"/>
		<axis xyz="0 1 0"/>
		<parent link="arm_link"/>
		<child link="bucket_cylinder_head_link"/>
	</joint>

	<joint name="bucket_cylinder_rod_joint" type="prismatic">
		<origin xyz="0 0 0"/>
		<axis xyz="-0.021529 0 -2.207579"/>
		<parent link="bucket_cylinder_head_link"/>
		<child link="bucket_cylinder_rod_link"/>
		<limit lower="-2" upper="2" effort="500" velocity="6.159937255"/>
		<mimic joint="bucket_joint" multiplier="${-0.9/-2.79}"/>
	</joint>
	<gazebo>
		<plugin name="bucket_cylinder_rod_joint_mimic_joint_plugin"
				filename="libroboticsgroup_upatras_gazebo_mimic_joint_plugin.so">
			<joint>bucket_joint</joint>
			<mimicJoint>bucket_cylinder_rod_joint</mimicJoint>
			<multiplier>${-0.9/-2.79}</multiplier>
			<offset>0</offset>
			<robotNamespace>/zx120</robotNamespace>
		</plugin>
	</gazebo>

	<joint name="bucket_b_joint" type="continuous">
		<origin xyz="0.330489 0 -2.150643"/>
		<axis xyz="0 1 0"/>
		<parent link="arm_link"/>
		<child link="bucket_b_link"/>
		<mimic joint="bucket_joint" multiplier="${120/160}"/>
	</joint>
	<gazebo>
		<plugin name="bucket_b_joint_mimic_joint_plugin"
				filename="libroboticsgroup_upatras_gazebo_mimic_joint_plugin.so">
			<joint>bucket_joint</joint>
			<mimicJoint>bucket_b_joint</mimicJoint>
			<multiplier>${120/160}</multiplier>
			<offset>0</offset>
			<robotNamespace>/zx120</robotNamespace>
		</plugin>
	</gazebo>

	<joint name="bucket_a_joint" type="continuous">
		<origin xyz="-0.182145 0 -0.315076"/>
		<axis xyz="0 1 0"/>
		<parent link="bucket_link"/>
		<child link="bucket_a_link"/>
		<mimic joint="bucket_joint" multiplier="${-92/160}"/>
	</joint>
	<gazebo>
		<plugin name="bucket_a_joint_mimic_joint_plugin"
				filename="libroboticsgroup_upatras_gazebo_mimic_joint_plugin.so">
			<joint>bucket_joint</joint>
			<mimicJoint>bucket_a_joint</mimicJoint>
			<multiplier>${-92/160}</multiplier>
			<offset>0</offset>
			<robotNamespace>/zx120</robotNamespace>
		</plugin>
	</gazebo>

	<link name="boom_link">
		<visual>
			<origin xyz="0 0 0"/>
			<geometry>
				<mesh filename="package://zx120_description/meshes/zx120-boom.dae"/>
			</geometry>
		</visual>

		<collision>
			<origin xyz="0 0 0"/>
			<geometry>
				<mesh filename="package://zx120_description/meshes/zx120-boom.dae"/>
			</geometry>
		</collision>

		<inertial>
			<origin xyz="2.091062 0.055029 0.975556" rpy="0 0 0"/>
			<mass value="0.03"/>
			<inertia ixx="1.0" ixy="0.0" ixz="0.0"
								iyy="1.0" iyz="0.0"
											izz="1.0"/>
		</inertial>
	</link>

	<joint name="arm_joint" type="revolute">
		<origin xyz="4.2241 0 1.7311"/>
		<axis xyz="0 1 0"/>
		<parent link="boom_link"/>
		<child link="arm_link"/>
		<limit lower="${radians(-70)}" upper="${radians(50)}" effort="500" velocity="6.159937255"/>
	</joint>

	<link name="arm_link">
		<visual>
			<origin xyz="0 0 0"/>
			<geometry>
				<mesh filename="package://zx120_description/meshes/zx120-arm.dae"/>
			</geometry>
		</visual>

		<collision>
			<origin xyz="0 0 0"/>
			<geometry>
				<mesh filename="package://zx120_description/meshes/zx120-arm.dae"/>
			</geometry>
		</collision>

		<inertial>
			<origin xyz="0.305996 0.000026 -0.912806" rpy="0 0 0"/>
			<mass value="0.03"/>
			<inertia ixx="1.0" ixy="0.0" ixz="0.0"
								iyy="1.0" iyz="0.0"
											izz="1.0"/>
		</inertial>
	</link>

	<!-- bucket axis -->
	<joint name="bucket_joint" type="revolute">
		<origin xyz="0.35383 0 -2.4712"/>
		<axis xyz="0 1 0"/>
		<parent link="arm_link"/>
		<child link="bucket_link"/>
		<limit lower="${radians(-160)}" upper="0" effort="500" velocity="6.159937255"/>
	</joint>

	<link name="bucket_link">
		<visual>
			<origin xyz="0 0 0"/>
			<geometry>
				<mesh filename="package://zx120_description/meshes/zx120-bucket.dae"/>
			</geometry>
		</visual>

		<collision>
			<origin xyz="0 0 0"/>
			<geometry>
				<mesh filename="package://zx120_description/meshes/zx120-bucket.dae"/>
			</geometry>
		</collision>

		<inertial>
			<origin xyz="-0.442405 0.001740 0.247894" rpy="0 0 0"/>
			<mass value="0.03"/>
			<inertia ixx="1.0" ixy="0.0" ixz="0.0"
								iyy="1.0" iyz="0.0"
											izz="1.0"/>
		</inertial>
	</link>

	<link name="boom_cylinder_head_link">
		<visual>
			<origin xyz="0 0 0"/>
			<geometry>
				<mesh filename="package://zx120_description/meshes/zx120-boom-cyl1.dae"/>
			</geometry>
		</visual>

		<collision>
			<origin xyz="0 0 0"/>
			<geometry>
				<mesh filename="package://zx120_description/meshes/zx120-boom-cyl1.dae"/>
			</geometry>
		</collision>

		<inertial>
			<origin xyz="0.241225 0.000050 0.577034" rpy="0 0 0"/>
			<mass value="0.03"/>
			<inertia ixx="1.0" ixy="0.0" ixz="0.0"
								iyy="1.0" iyz="0.0"
											izz="1.0"/>
		</inertial>
	</link>

	<link name="boom_cylinder_rod_link">
		<visual>
			<origin xyz="0 0 0"/>
			<geometry>
				<mesh filename="package://zx120_description/meshes/zx120-boom-cyl2.dae"/>
			</geometry>
		</visual>

		<collision>
			<origin xyz="0 0 0"/>
			<geometry>
				<mesh filename="package://zx120_description/meshes/zx120-boom-cyl2.dae"/>
			</geometry>
		</collision>

		<inertial>
			<origin xyz="0.558044 0.000050 1.286359" rpy="0 0 0"/>
			<mass value="0.03"/>
			<inertia ixx="1.0" ixy="0.0" ixz="0.0"
								iyy="1.0" iyz="0.0"
											izz="1.0"/>
		</inertial>
	</link>

	<link name="arm_cylinder_head_link">
		<visual>
			<origin xyz="0 0 0"/>
			<geometry>
				<mesh filename="package://zx120_description/meshes/zx120-arm-cyl1.dae"/>
			</geometry>
		</visual>

		<collision>
			<origin xyz="0 0 0"/>
			<geometry>
				<mesh filename="package://zx120_description/meshes/zx120-arm-cyl1.dae"/>
			</geometry>
		</collision>

		<inertial>
			<origin xyz="0.696672 0.000026 -0.000065" rpy="0 0 0"/>
			<mass value="0.03"/>
			<inertia ixx="1.0" ixy="0.0" ixz="0.0"
								iyy="1.0" iyz="0.0"
											izz="1.0"/>
		</inertial>
	</link>

	<link name="arm_cylinder_rod_link">
		<visual>
			<origin xyz="0 0 0"/>
			<geometry>
				<mesh filename="package://zx120_description/meshes/zx120-arm-cyl2.dae"/>
			</geometry>
		</visual>

		<collision>
			<origin xyz="0 0 0"/>
			<geometry>
				<mesh filename="package://zx120_description/meshes/zx120-arm-cyl2.dae"/>
			</geometry>
		</collision>

		<inertial>
			<origin xyz="1.686736 -0.001027 -0.000662" rpy="0 0 0"/>
			<mass value="0.03"/>
			<inertia ixx="1.0" ixy="0.0" ixz="0.0"
								iyy="1.0" iyz="0.0"
											izz="1.0"/>
		</inertial>
	</link>

	<link name="bucket_cylinder_head_link">
		<visual>
			<origin xyz="0 0 0"/>
			<geometry>
				<mesh filename="package://zx120_description/meshes/zx120-bucket-cyl1.dae"/>
			</geometry>
		</visual>

		<collision>
			<origin xyz="0 0 0"/>
			<geometry>
				<mesh filename="package://zx120_description/meshes/zx120-bucket-cyl1.dae"/>
			</geometry>
		</collision>

		<inertial>
			<origin xyz="-0.010342 0.000321 -0.639293" rpy="0 0 0"/>
			<mass value="0.03"/>
			<inertia ixx="1.0" ixy="0.0" ixz="0.0"
								iyy="1.0" iyz="0.0"
											izz="1.0"/>
		</inertial>
	</link>

	<link name="bucket_cylinder_rod_link">
		<visual>
			<origin xyz="0 0 0"/>
			<geometry>
				<mesh filename="package://zx120_description/meshes/zx120-bucket-cyl2.dae"/>
			</geometry>
		</visual>

		<collision>
			<origin xyz="0 0 0"/>
			<geometry>
				<mesh filename="package://zx120_description/meshes/zx120-bucket-cyl2.dae"/>
			</geometry>
		</collision>

		<inertial>
			<origin xyz="-0.015456 0.000321 -1.701647" rpy="0 0 0"/>
			<mass value="0.03"/>
			<inertia ixx="1.0" ixy="0.0" ixz="0.0"
								iyy="1.0" iyz="0.0"
											izz="1.0"/>
		</inertial>
	</link>

	<link name="bucket_b_link">
		<visual>
			<origin xyz="0 0 0"/>
			<geometry>
				<mesh filename="package://zx120_description/meshes/zx120-p1.dae"/>
			</geometry>
		</visual>

		<collision>
			<origin xyz="0 0 0"/>
			<geometry>
				<mesh filename="package://zx120_description/meshes/zx120-p1.dae"/>
			</geometry>
		</collision>

		<inertial>
			<origin xyz="0.126203 0.000026 -0.212651" rpy="0 0 0"/>
			<mass value="0.03"/>
			<inertia ixx="1.0" ixy="0.0" ixz="0.0"
								iyy="1.0" iyz="0.0"
											izz="1.0"/>
		</inertial>
	</link>

	<link name="bucket_a_link">
		<visual>
			<origin xyz="0 0 0"/>
			<geometry>
				<mesh filename="package://zx120_description/meshes/zx120-p2.dae"/>
			</geometry>
		</visual>

		<collision>
			<origin xyz="0 0 0"/>
			<geometry>
				<mesh filename="package://zx120_description/meshes/zx120-p2.dae"/>
			</geometry>
		</collision>

		<inertial>
			<origin xyz="0.211197 0.000576 0.111406" rpy="0 0 0"/>
			<mass value="0.03"/>
			<inertia ixx="1.0" ixy="0.0" ixz="0.0"
								iyy="1.0" iyz="0.0"
											izz="1.0"/>
		</inertial>
	</link>

	<transmission name="tran1">
		<type>transmission_interface/SimpleTransmission</type>
		<joint name="swing_joint">
			<hardwareInterface>hardware_interface/PositionJointInterface</hardwareInterface>
		</joint>
		<actuator name="motor1">
			<hardwareInterface>hardware_interface/PositionJointInterface</hardwareInterface>
			<mechanicalReduction>1</mechanicalReduction>
		</actuator>
	</transmission>

	<transmission name="tran2">
		<type>transmission_interface/SimpleTransmission</type>
		<joint name="boom_joint">
			<hardwareInterface>hardware_interface/PositionJointInterface</hardwareInterface>
		</joint>
		<actuator name="motor2">
			<hardwareInterface>hardware_interface/PositionJointInterface</hardwareInterface>
			<mechanicalReduction>1</mechanicalReduction>
		</actuator>
	</transmission>

	<transmission name="tran3">
		<type>transmission_interface/SimpleTransmission</type>
		<joint name="arm_joint">
			<hardwareInterface>hardware_interface/PositionJointInterface</hardwareInterface>
		</joint>
		<actuator name="motor3">
			<hardwareInterface>hardware_interface/PositionJointInterface</hardwareInterface>
			<mechanicalReduction>1</mechanicalReduction>
		</actuator>
	</transmission>

	<transmission name="tran4">
		<type>transmission_interface/SimpleTransmission</type>
		<joint name="bucket_joint">
			<hardwareInterface>hardware_interface/PositionJointInterface</hardwareInterface>
		</joint>
		<actuator name="motor4">
			<hardwareInterface>hardware_interface/PositionJointInterface</hardwareInterface>
			<mechanicalReduction>1</mechanicalReduction>
		</actuator>
	</transmission>

</robot>
